Workbook
Name CommentVC: Data!$S$9
Name CoverVC: Data!$T$9
Name EnterpriseVC: Data!$I$9
Name HostedSecurityVC: Data!#REF!
Name IsPublicVC: Data!$G$9
Name ManagedVC: Data!#REF!
Name ManagedVC: Data!#REF!
Name ManagedVC: Data!#REF!
Name ManagedVC: Data!#REF!
Name ManagedVC: Data!#REF!
Name ManagedVC: Data!#REF!
Name ManagedVC: Data!#REF!
Name ManagedVC: Data!#REF!
Name ManagedVC: Data!#REF!
Name ManagedVC: Data!#REF!
Name ManagedVC: Data!#REF!
Name ManagedVC: Data!#REF!
Name ManagedVC: Data!#REF!
Name ManagedVC: Data!#REF!
Name ManagedVC: Data!#REF!
Name ManagedVC: Data!#REF!
Name ManagedVC: Data!#REF!
Name ManagedVC: Data!#REF!
Name MediaVC: Data!$N$9
Name MigrationVC: Data!$R$9
Name ProductCompositionMatrixVC: Data!$Q$9
Name ProductCompositionVC: Data!$P$9
Name ProductSelectorVC: Data!$O$9
Name PSLicenseType: Data!$A$108:$A$115
Name PSTerm: Data!$A$101:$A$103
Name SOHOVC: Data!$H$9
Name TrafficVC: Data!$M$9
Name xSPVC: Data!$L$9

Sheet Main
B7: =CONCATENATE("Price List applicable for ",Data!A9,". Effective from ",Data!A11,". ") -> Price List applicable for Vietnam. Effective from July 1, 2026.
B8: =CONCATENATE(Data!A5,". ",Data!A7) -> Kaspersky Lab. 39A/3 Leningradskoe Shosse Moscow, 125212. 0
B9: Table of contents
B10: Price list | C10: Home+SOHO | D10: Home user, Small and Home office products. | G10: +
C11: CBA Subscription | D11: CBA Subscription. | G11: -
C12: SMB+Enterprise (License) | D12: SMB and Enterprise products. Commercial licenses. | G12: +
C13: SMB+Enterprise (Pack) | D13: SMB and Enterprise products. Commercial packs. | G13: +
C14: Subscription&MSP | D14: Subscription&MSP. | G14: +
C15: Professional Services | D15: Professional Services. | G15: +
C16: Security Services | D16: Security Services. | G16: +
C17: xSP | D17: Licences for ISP/ASP. | G17: =xSPVC -> 0
C18: Traffic | D18: Traffic licenses. | G18: =TrafficVC -> 0
C19: SIEM | D19: SIEM. | G19: +
C20: Scan Engine | D20: Scan Engine. | G20: +
C21: SD-WAN | D21: SD-WAN. | G21: +
C22: ATC | D22: Authorized Training Center | G22: +
B23: Additional Data | C23: Comment | D23: Description of pricing rules and licensing. | G23: =CommentVC -> +

Sheet Home+SOHO
C7: =CONCATENATE("Price List applicable for ",Data!A9,". Effective from ",Data!A11,". ") -> Price List applicable for Vietnam. Effective from July 1, 2026.
C8: =CONCATENATE(Data!A5,". ",Data!A7) -> Kaspersky Lab. 39A/3 Leningradskoe Shosse Moscow, 125212. 0
B9: Max of Price | H9: Type | I9: Term
H10: Base | L10: Renewal
B11: Code | C11: Product | D11: Package | E11: Volume | F11: LicenceObject | G11: SKU | H11: 1 month | I11: 1 year | J11: 2 year | K11: 3 year | L11: 1 year | M11: 2 year | N11: 3 year
B12: 1000 | C12: New 2022 Product Line | D12: - | E12: - | F12: - | G12: -
B13: 1001 | C13: Kaspersky Standard | D13: Retail Pack | E13: 1Dvc | G13: KL1041WUA** | I13: 290909.09 | J13: 581818.18
E14: 3Dvc | G14: KL1041WUC** | I14: 513636.36 | J14: 1027272.7
E15: 5Dvc | G15: KL1041WUE** | I15: 660000 | J15: 1320000
E16: 10Dvc | G16: KL1041WUK** | I16: 940000 | J16: 1880000
D17: Download Pack | E17: 1Dvc | G17: KL1041WDA** | I17: 290909.09 | J17: 581818.18
E18: 3Dvc | G18: KL1041WDC** | I18: 513636.36 | J18: 1027272.7
E19: 5Dvc | G19: KL1041WDE** | I19: 660000 | J19: 1320000
E20: 10Dvc | G20: KL1041WDK** | I20: 940000 | J20: 1880000
B21: 1002 | C21: Kaspersky Plus | D21: Retail Pack | E21: 1Dvc | G21: KL1042WUA** | I21: 456363.64 | J21: 912727.27
E22: 3Dvc | G22: KL1042WUC** | I22: 672727.27 | J22: 1345454.5
E23: 5Dvc | G23: KL1042WUE** | I23: 796363.64 | J23: 1592727.3
E24: 10Dvc | G24: KL1042WUK** | I24: 999090.91 | J24: 1998181.8
D25: Download Pack | E25: 1Dvc | G25: KL1042WDA** | I25: 456363.64 | J25: 912727.27
E26: 3Dvc | G26: KL1042WDC** | I26: 672727.27 | J26: 1345454.5
E27: 5Dvc | G27: KL1042WDE** | I27: 796363.64 | J27: 1592727.3
E28: 10Dvc | G28: KL1042WDK** | I28: 999090.91 | J28: 1998181.8
B29: 1003 | C29: Kaspersky Premium + Customer Support | D29: Retail Pack | E29: 1Dvc | G29: KL1047WUA** | I29: 578181.82 | J29: 1156363.6
E30: 3Dvc | G30: KL1047WUC** | I30: 790909.09 | J30: 1581818.2
E31: 5Dvc | G31: KL1047WUE** | I31: 935454.55 | J31: 1870909.1
E32: 10Dvc | G32: KL1047WUK** | I32: 1134545.5 | J32: 2269090.9
D33: Download Pack | E33: 1Dvc | G33: KL1047WDA** | I33: 578181.82 | J33: 1156363.6
E34: 3Dvc | G34: KL1047WDC** | I34: 790909.09 | J34: 1581818.2
E35: 5Dvc | G35: KL1047WDE** | I35: 935454.55 | J35: 1870909.1
E36: 10Dvc | G36: KL1047WDK** | I36: 1134545.5 | J36: 2269090.9
E37: 20Dvc | G37: KL1047WDN** | I37: 1537272.7 | J37: 3074545.5
B38: 1004 | C38: Kaspersky Standard Mobile | D38: Retail Pack | E38: 1Dvc | G38: KL1048WUA** | I38: 190000
D39: Download Pack | E39: 1Dvc | G39: KL1048WDA** | I39: 190000
B40: 1005 | C40: Kaspersky Premium Mobile | D40: Retail Pack | E40: 1Dvc | F40: Dvc | G40: KL1004WUA** | I40: 462727.27
D41: Download Pack | E41: 1Dvc | F41: Dvc | G41: KL1004WDA** | I41: 462727.27
B42: 1200 | C42: Other | D42: - | E42: - | F42: - | G42: -
B43: 1201 | C43: Kaspersky Secure Connection | D43: Download Pack | E43: 5Dvc | G43: KL1987WDE** | H43: 117273 | I43: 620000
B44: 1202 | C44: Kaspersky Cloud Password Manager | D44: Download Pack | E44: 1User | F44: User | G44: KL1956WDA** | I44: 373636.36
B45: 1203 | C45: Kaspersky Safe Kids | D45: Retail Pack | E45: 1User | G45: KL1962WUA** | I45: 373636.36
D46: Download Pack | E46: 1User | G46: KL1962WDA** | I46: 373636.36
...

Sheet CBA Subscription
C7: =CONCATENATE("Price List applicable for ",Data!A9,". Effective from ",Data!A11,". ") -> Price List applicable for Vietnam. Effective from July 1, 2026. | H7: * For additional details please see
C8: =CONCATENATE(Data!A5,". ",Data!A7) -> Kaspersky Lab. 39A/3 Leningradskoe Shosse Moscow, 125212. 0 | H8: specifications in Comment section
B9: Max of Price | H9: Type | I9: Term
H10: Subscription Limit
B11: Code | C11: Product | D11: Package | E11: Volume | F11: LicenceObject | G11: SKU | H11: 1 year
B12: 1000 | C12: New 2022 Product Line | D12: - | E12: - | F12: - | G12: -
B13: 1001 | C13: Kaspersky Standard | D13: xSP Pack | E13: 1Dvc | G13: KL10414GA** | H13: 43.52
E14: 3Dvc | G14: KL10414GC** | H14: 68.52
E15: 5Dvc | G15: KL10414GE** | H15: 87.96
E16: 10Dvc | G16: KL10414GK** | H16: 125
B17: 1002 | C17: Kaspersky Plus | D17: xSP Pack | E17: 1Dvc | G17: KL10424GA** | H17: 62.96
E18: 3Dvc | G18: KL10424GC** | H18: 87.96
E19: 5Dvc | G19: KL10424GE** | H19: 106.48
E20: 10Dvc | G20: KL10424GK** | H20: 144.44
B21: 1003 | C21: Kaspersky Premium + Customer Support | D21: xSP Pack | E21: 1Dvc | G21: KL10474GA** | H21: 99.07
E22: 3Dvc | G22: KL10474GC** | H22: 124.07
E23: 5Dvc | G23: KL10474GE** | H23: 143.52
E24: 10Dvc | G24: KL10474GK** | H24: 180.56
E25: 20Dvc | G25: KL10474GN** | H25: 243.52
B26: 1100 | C26: Frontline | D26: - | E26: - | F26: - | G26: -
B27: 1101 | C27: Kaspersky Anti-Virus | D27: xSP Pack | E27: 1Dt | G27: KL11714GA** | H27: 27.95
E28: 3Dt | G28: KL11714GC** | H28: 43.95
E29: 5Dt | G29: KL11714GE** | H29: 69.95
B30: 1102 | C30: Kaspersky Internet Security | D30: xSP Pack | E30: 1Dvc | G30: KL19394GA** | H30: 40.95
E31: 3Dvc | G31: KL19394GC** | H31: 77.95
E32: 5Dvc | G32: KL19394GE** | H32: 109.95
E33: 10Dvc | G33: KL19394GK** | H33: 165.95
B34: 1103 | C34: Kaspersky Total Security | D34: xSP Pack | E34: 1Dvc | G34: KL19494GA** | H34: 61.95
E35: 3Dvc | G35: KL19494GC** | H35: 94.95
E36: 5Dvc | G36: KL19494GE** | H36: 135.95
B37: 1200 | C37: Other | D37: - | E37: - | F37: - | G37: -
B38: 1201 | C38: Kaspersky Cloud Password Manager | D38: xSP Pack | E38: 1User | F38: User | G38: KL19564GA** | H38: 19.32
B39: 1202 | C39: Kaspersky Safe Kids | D39: xSP Pack | E39: 1User | G39: KL19624GA** | H39: 22.22
B40: 1203 | C40: Kaspersky Secure Connection | D40: xSP Pack | E40: 5Dvc | G40: KL19874GE** | H40: 38.89

Sheet SMB+Enterprise (License)
C7: =CONCATENATE("Price List applicable for ",Data!A9,". Effective from ",Data!A11,". ") -> Price List applicable for Vietnam. Effective from July 1, 2026. | M7: * For additional details on Kaspersky Security for Virtualization, Kaspersky Data Leakage Protection products
C8: =CONCATENATE(Data!A5,". ",Data!A7) -> Kaspersky Lab. 39A/3 Leningradskoe Shosse Moscow, 125212. 0 | O8: please see specifications in Comment section
B9: Max of Price | J9: Band
B10: Code | C10: Product | D10: LicenceDescription | E10: Package | F10: LicenceObject | G10: Type | H10: Term | I10: SKU | J10: Band M: 15-19 | K10: Band N: 20-24 | L10: Band P: 25-49 | M10: Band Q: 50-99 | N10: Band R: 100-149
B11: 2003 | C11: Kaspersky Next EDR Optimum | E11: License | G11: Base Plus | H11: 1 year | I11: KL4066WA*F8 | J11: 2402400 | K11: 2402400 | L11: 2180640 | M11: 1928850 | N11: 1732500
H12: 2 year | I12: KL4066WA*D8 | J12: 3603600 | K12: 3603600 | L12: 3280200 | M12: 2887500 | N12: 2610300
H13: 3 year | I13: KL4066WA*T8 | J13: 4458300 | K13: 4458300 | L13: 4042500 | M13: 3557400 | N13: 3210900
G14: Renewal Plus | H14: 1 year | I14: KL4066WA*F9 | J14: 1924230 | K14: 1924230 | L14: 1744050 | M14: 1543080 | N14: 1388310
H15: 2 year | I15: KL4066WA*D9 | J15: 3164700 | K15: 3164700 | L15: 2887500 | M15: 2541000 | N15: 2286900
H16: 3 year | I16: KL4066WA*T9 | J16: 3903900 | K16: 3903900 | L16: 3557400 | M16: 3141600 | N16: 2818200

Sheet SMB+Enterprise (Pack)
C7: =CONCATENATE("Price List applicable for ",Data!A9,". Effective from ",Data!A11,". ") -> Price List applicable for Vietnam. Effective from July 1, 2026. | AD7: * For additional details on Acronis Backup Advanced Universa product
C8: =CONCATENATE(Data!A5,". ",Data!A7) -> Kaspersky Lab. 39A/3 Leningradskoe Shosse Moscow, 125212. 0 | AD8: please see specifications in Comment section
B9: Max of Price | J9: Band
B10: Code | C10: Product | D10: LicenceDescription | E10: Package | F10: LicenceObject | G10: Type | H10: Term | I10: SKU | K10: Band A: 1 | L10: Band B: 2 | M10: Band C: 3 | N10: Band D: 4 | O10: Band E: 5 | P10: Band F: 6 | Q10: Band H: 8 | R10: Band K: 10 | S10: Band L: 12 | T10: Band 2: 16 | U10: Band N: 20 | V10: Band Q: 50 | W10: Band R: 100 | X10: Band S: 150 | Y10: Band T: 250 | Z10: Band U: 500 | AA10: Band V: 1000 | AB10: Band W: 2500 | AC10: Band X: 5000 | AD10: Band Y: 10000
B11: 8000 | C11: Threat Intelligence* | D11: (blank) | E11: - | F11: - | G11: - | H11: - | I11: -
B12: 8001 | C12: Kaspersky Online Security Trainings for Experts. Targeted Malware Reverse Engineering | D12: Trainee | E12: License Pack | G12: Base | H12: 6 months | I12: KL7580WC*HS | K12: 41510700
B13: 8002 | C13: Kaspersky Online Security Trainings for Experts.Yara | D13: Trainee | E13: License Pack | G13: Base | H13: 6 months | I13: KL7579WC*HS | K13: 22314600
B14: 8003 | C14: Kaspersky Online Security Trainings for Experts. Advanced Malware Analysis Techniques | D14: Trainee | E14: License Pack | G14: Base | H14: 6 months | I14: KL7590WC*HS | K14: 79233000
B15: 8004 | C15: Kaspersky Online Security Trainings for Experts. Windows Incident Response | D15: Trainee | E15: License Pack | G15: Base | H15: 6 months | I15: KL7518WC*HS | K15: 30884700
B16: 8005 | C16: Kaspersky Online Security Trainings For Experts. Security Operations And Threat Hunting | D16: Trainee | E16: License Pack | G16: Base | H16: 6 months | I16: KL7510WC*HS | K16: 41834100
B17: 8006 | C17: Kaspersky Online Security Trainings For Experts. Reverse Engineering 101 | D17: Trainee | E17: License Pack | G17: Base | H17: 6 months | I17: KL7511WC*HS | K17: 24370500
B18: 8007 | C18: Kaspersky Online Security Trainings For Experts. Mobile Malware Reverse Engineering | D18: Trainee | E18: License Pack | G18: Base | H18: 6 months | I18: KL7578WC*HS | K18: 23515800
B19: 8008 | C19: Kaspersky Online Security Trainings For Experts. Suricata for Incident Response and Threat Hunting | D19: Trainee | E19: License Pack | G19: Base | H19: 6 months | I19: KL7512WC*HS | K19: 26611200
B20: 8009 | C20: Kaspersky Online Security Trainings For Experts. Advanced malware reverse engineering with Ghidra | D20: Trainee | E20: License Pack | G20: Base | H20: 6 months | I20: KL7513WC*HS | K20: 53823000
B21: 8011 | C21: Kaspersky Online Security Trainings For Experts. Windows Digital Forensics | E21: License Pack | G21: Base | H21: 6 months | I21: KL7514WC*HS | K21: 37745400
B22: 8012 | C22: Kaspersky Online Security Trainings For Experts. LLM Security | D22: Trainee | E22: License Pack | F22: Trainee | G22: Base | H22: 6 months | I22: KL7403WC*HS | K22: 22176000
B23: 8016 | C23: Kaspersky Private Security Network, Standard | D23: Instance | E23: License Pack | G23: Base Plus | H23: 1 year | I23: KL8552WC*F8 | K23: 3182232900
H24: 2 year | I24: KL8552WC*D8 | K24: 4773314700
H25: 3 year | I25: KL8552WC*T8 | K25: 6364442700
G26: Renewal Plus | H26: 1 year | I26: KL8552WC*F9 | K26: 2227533000
H27: 2 year | I27: KL8552WC*D9 | K27: 3341345700
H28: 3 year | I28: KL8552WC*T9 | K28: 4455112200
B29: 8017 | C29: Kaspersky Private Security Network, Advanced | D29: Instance | E29: License Pack | G29: Base Plus | H29: 1 year | I29: KL8553WC*F8 | R29: 7425194700
H30: 2 year | I30: KL8553WC*D8 | R30: 11137757400
H31: 3 year | I31: KL8553WC*T8 | R31: 14850366300
G32: Renewal Plus | H32: 1 year | I32: KL8553WC*F9 | R32: 5197615500
H33: 2 year | I33: KL8553WC*D9 | R33: 7796457900
H34: 3 year | I34: KL8553WC*T9 | R34: 10395254100
B35: 8018 | C35: Kaspersky Cloud Sandbox | D35: Queries per day | E35: License Pack | G35: Base Plus | H35: 1 year | I35: KL7953WC*F8 | R35: 249041100 | U35: 415083900 | V35: 705635700 | W35: 1245228600 | Z35: 1867842900 | AA35: 2697987600 | AC35: 3943170000
H36: 2 year | I36: KL7953WC*D8 | R36: 448278600 | U36: 747123300 | V36: 1270130400 | W36: 2241393000 | Z36: 3362089500 | AA36: 4856359200 | AC36: 7097729100
H37: 3 year | I37: KL7953WC*T8 | R37: 635065200 | U37: 1058418900 | V37: 1799328300 | W37: 3175302900 | Z37: 4762942800 | AA37: 6879826800 | AC37: 10055129700
G38: Renewal Plus | H38: 1 year | I38: KL7953WC*F9 | R38: 236590200 | U38: 394317000 | V38: 670338900 | W38: 1182974100 | Z38: 1774426500 | AA38: 2563083600 | AC38: 3746011500
H39: 2 year | I39: KL7953WC*D9 | R39: 425871600 | U39: 709770600 | V39: 1206628500 | W39: 2129334900 | Z39: 3193990800 | AA39: 4613532000 | AC39: 6742843800
H40: 3 year | I40: KL7953WC*T9 | R40: 603302700 | U40: 1005519900 | V40: 1709376900 | W40: 3016559700 | Z40: 4524804900 | AA40: 6535844700 | AC40: 9552381300
B41: 8019 | C41: Kaspersky Research Sandbox* | D41: Queries per day | E41: License Pack | G41: Base Plus | H41: 1 year | I41: KL7954WC*F8 | J41: 14527543800 | W41: 830144700 | Y41: 1867842900 | AA41: 3943170000
H42: 2 year | I42: KL7954WC*D8 | J42: 26668880700 | W42: 1523930100 | Y42: 3428848500 | AA42: 7238708400
H43: 3 year | I43: KL7954WC*T8 | J43: 37055726400 | W43: 2117461500 | Y43: 4764305700 | AA43: 10057994100
G44: Renewal Plus | H44: 1 year | I44: KL7954WC*F9 | J44: 13895897400 | W44: 794062500 | Y44: 1786623300 | AA44: 3771744900
H45: 2 year | I45: KL7954WC*D9 | J45: 25405634100 | W45: 1451742600 | Y45: 3266432400 | AA45: 6895812000
H46: 3 year | I46: KL7954WC*T9 | J46: 35202944700 | W46: 2011617300 | Y46: 4526098500 | AA46: 9555084000
...

Sheet Subscription&MSP
C7: =CONCATENATE("Price List applicable for ",Data!A9,". Effective from ",Data!A11,". ") -> Price List applicable for Vietnam. Effective from July 1, 2026. | AB7: * For additional details on Acronis Backup Advanced Universa product
C8: =CONCATENATE(Data!A5,". ",Data!A7) -> Kaspersky Lab. 39A/3 Leningradskoe Shosse Moscow, 125212. 0 | AB8: please see specifications in Comment section
B9: Max of Price | J9: Band
B10: Code | C10: Product | D10: LicenceDescription | E10: Package | F10: LicenceObject | G10: Type | H10: Term | I10: SKU | J10: Band Z: 1-1 | K10: Band A: 1-1 | L10: Band B: 2-2 | M10: Band C: 3-3 | N10: Band D: 4-4 | O10: Band E: 5-9 | P10: Band K: 10-14 | Q10: Band M: 15-19 | R10: Band N: 20-24 | S10: Band P: 25-49 | T10: Band Q: 50-99 | U10: Band R: 100-149 | V10: Band S: 150-249 | W10: Band T: 250-499 | X10: Band U: 500-999 | Y10: Band V: 1000-1499 | Z10: Band W: 1500-2499 | AA10: Band X: 2500-4999 | AB10: Band Y: 5000+
B11: 2000 | C11: Kaspersky NEXT | D11: (blank) | E11: - | F11: - | G11: - | H11: - | I11: -
B12: 2002 | C12: Kaspersky Next EDR Foundations | E12: License | G12: Successive | H12: 1 month | I12: KL4065WA*MG | K12: 139755 | L12: 139755 | M12: 139755 | N12: 139755 | O12: 139755 | P12: 139755 | Q12: 139755 | R12: 139755 | S12: 129591 | T12: 114345 | U12: 101640 | V12: 101640 | W12: 91476 | X12: 81312 | Y12: 68607 | Z12: 63525 | AA12: 53361 | AB12: 50820
H13: 1 year | I13: KL4065WA*FG | K13: 1397550 | L13: 1397550 | M13: 1397550 | N13: 1397550 | O13: 1397550 | P13: 1397550 | Q13: 1397550 | R13: 1397550 | S13: 1295910 | T13: 1143450 | U13: 1016400 | V13: 1016400 | W13: 914760 | X13: 813120 | Y13: 686070 | Z13: 635250 | AA13: 533610 | AB13: 508200
H14: 2 year | I14: KL4065WA*DG | K14: 2097480 | L14: 2097480 | M14: 2097480 | N14: 2097480 | O14: 2097480 | P14: 2097480 | Q14: 2097480 | R14: 2097480 | S14: 1945020 | T14: 1716330 | U14: 1524600 | V14: 1524600 | W14: 1372140 | X14: 1219680 | Y14: 1030260 | Z14: 954030 | AA14: 801570 | AB14: 762300
H15: 3 year | I15: KL4065WA*TG | K15: 2587200 | L15: 2587200 | M15: 2587200 | N15: 2587200 | O15: 2587200 | P15: 2587200 | Q15: 2587200 | R15: 2587200 | S15: 2402400 | T15: 2113650 | U15: 1880340 | V15: 1880340 | W15: 1693230 | X15: 1503810 | Y15: 1270500 | Z15: 1173480 | AA15: 986370 | AB15: 940170
G16: Successive Plus | H16: 1 month | I16: KL4065WA*M4 | K16: 152460 | L16: 152460 | M16: 152460 | N16: 152460 | O16: 152460 | P16: 152460 | Q16: 152460 | R16: 152460 | S16: 142296 | T16: 127050 | U16: 111804 | V16: 111804 | W16: 101640 | X16: 88935 | Y16: 76230 | Z16: 71148 | AA16: 58443 | AB16: 55902
H17: 1 year | I17: KL4065WA*F4 | K17: 1538460 | L17: 1538460 | M17: 1538460 | N17: 1538460 | O17: 1538460 | P17: 1538460 | Q17: 1538460 | R17: 1538460 | S17: 1425270 | T17: 1258950 | U17: 1118040 | V17: 1118040 | W17: 1007160 | X17: 893970 | Y17: 755370 | Z17: 699930 | AA17: 586740 | AB17: 559020
H18: 2 year | I18: KL4065WA*D4 | K18: 2310000 | L18: 2310000 | M18: 2310000 | N18: 2310000 | O18: 2310000 | P18: 2310000 | Q18: 2310000 | R18: 2310000 | S18: 2136750 | T18: 1884960 | U18: 1677060 | V18: 1677060 | W18: 1508430 | X18: 1342110 | Y18: 1134210 | Z18: 1046430 | AA18: 880110 | AB18: 838530
H19: 3 year | I19: KL4065WA*T4 | K19: 2841300 | L19: 2841300 | M19: 2841300 | N19: 2841300 | O19: 2841300 | P19: 2841300 | Q19: 2841300 | R19: 2841300 | S19: 2633400 | T19: 2333100 | U19: 2067450 | V19: 2067450 | W19: 1861860 | X19: 1653960 | Y19: 1395240 | Z19: 1293600 | AA19: 1085700 | AB19: 1034880
B20: 2003 | C20: Kaspersky Next EDR Optimum | E20: License | G20: Successive | H20: 1 month | I20: KL4066WA*MG | K20: 218526 | L20: 218526 | M20: 218526 | N20: 218526 | O20: 218526 | P20: 218526 | Q20: 218526 | R20: 218526 | S20: 198198 | T20: 175329 | U20: 157542 | V20: 157542 | W20: 142296 | X20: 129591 | Y20: 114345 | Z20: 104181 | AA20: 91476 | AB20: 86394
H21: 1 year | I21: KL4066WA*FG | K21: 2185260 | L21: 2185260 | M21: 2185260 | N21: 2185260 | O21: 2185260 | P21: 2185260 | Q21: 2185260 | R21: 2185260 | S21: 1981980 | T21: 1753290 | U21: 1575420 | V21: 1575420 | W21: 1422960 | X21: 1295910 | Y21: 1143450 | Z21: 1041810 | AA21: 914760 | AB21: 863940
H22: 2 year | I22: KL4066WA*DG | K22: 3280200 | L22: 3280200 | M22: 3280200 | N22: 3280200 | O22: 3280200 | P22: 3280200 | Q22: 3280200 | R22: 3280200 | S22: 2979900 | T22: 2633400 | U22: 2356200 | V22: 2356200 | W22: 2134440 | X22: 1945020 | Y22: 1716330 | Z22: 1563870 | AA22: 1372140 | AB22: 1295910
H23: 3 year | I23: KL4066WA*TG | K23: 4042500 | L23: 4042500 | M23: 4042500 | N23: 4042500 | O23: 4042500 | P23: 4042500 | Q23: 4042500 | R23: 4042500 | S23: 3672900 | T23: 3234000 | U23: 2910600 | V23: 2910600 | W23: 2633400 | X23: 2402400 | Y23: 2113650 | Z23: 1928850 | AA23: 1693230 | AB23: 1598520
G24: Successive Plus | H24: 1 month | I24: KL4066WA*M4 | K24: 241395 | L24: 241395 | M24: 241395 | N24: 241395 | O24: 241395 | P24: 241395 | Q24: 241395 | R24: 241395 | S24: 218526 | T24: 193116 | U24: 172788 | V24: 172788 | W24: 157542 | X24: 142296 | Y24: 127050 | Z24: 114345 | AA24: 101640 | AB24: 94017
H25: 1 year | I25: KL4066WA*F4 | K25: 2402400 | L25: 2402400 | M25: 2402400 | N25: 2402400 | O25: 2402400 | P25: 2402400 | Q25: 2402400 | R25: 2402400 | S25: 2180640 | T25: 1928850 | U25: 1732500 | V25: 1732500 | W25: 1566180 | X25: 1425270 | Y25: 1258950 | Z25: 1145760 | AA25: 1007160 | AB25: 949410
H26: 2 year | I26: KL4066WA*D4 | K26: 3603600 | L26: 3603600 | M26: 3603600 | N26: 3603600 | O26: 3603600 | P26: 3603600 | Q26: 3603600 | R26: 3603600 | S26: 3280200 | T26: 2887500 | U26: 2610300 | V26: 2610300 | W26: 2356200 | X26: 2136750 | Y26: 1884960 | Z26: 1718640 | AA26: 1508430 | AB26: 1425270
H27: 3 year | I27: KL4066WA*T4 | K27: 4458300 | L27: 4458300 | M27: 4458300 | N27: 4458300 | O27: 4458300 | P27: 4458300 | Q27: 4458300 | R27: 4458300 | S27: 4042500 | T27: 3557400 | U27: 3210900 | V27: 3210900 | W27: 2887500 | X27: 2633400 | Y27: 2333100 | Z27: 2118270 | AA27: 1861860 | AB27: 1757910
B28: 2004 | C28: Kaspersky Next EDR Expert | D28: User | E28: License | F28: User | G28: Successive Plus | H28: 1 month | I28: KL4069WA*M4 | W28: 443520 | X28: 334257 | Y28: 279510 | Z28: 270732 | AA28: 265650 | AB28: 263109
H29: 1 year | I29: KL4069WA*F4 | W29: 4435200 | X29: 3349500 | Y29: 2795100 | Z29: 2702700 | AA29: 2656500 | AB29: 2633400
H30: 2 year | I30: KL4069WA*D4 | W30: 7091700 | X30: 5359200 | Y30: 4481400 | Z30: 4342800 | AA30: 4250400 | AB30: 4204200
H31: 3 year | I31: KL4069WA*T4 | W31: 9979200 | X31: 7530600 | Y31: 6283200 | Z31: 6098400 | AA31: 5982900 | AB31: 5913600
B32: 2005 | C32: Kaspersky Next XDR Optimum | D32: User | E32: License | F32: User | G32: Successive | H32: 1 month | I32: KL4085WA*MG | O32: 284130 | P32: 284130 | Q32: 284130 | R32: 284130 | S32: 257565 | T32: 227997 | U32: 204897 | V32: 204897 | W32: 185031 | X32: 168399 | Y32: 148764 | Z32: 135366 | AA32: 118965 | AB32: 112266
H33: 1 year | I33: KL4085WA*FG | O33: 2841300 | P33: 2841300 | Q33: 2841300 | R33: 2841300 | S33: 2587200 | T33: 2286900 | U33: 2055900 | V33: 2055900 | W33: 1848000 | X33: 1683990 | Y33: 1487640 | Z33: 1353660 | AA33: 1189650 | AB33: 1122660
H34: 2 year | I34: KL4085WA*DG | O34: 4273500 | P34: 4273500 | Q34: 4273500 | R34: 4273500 | S34: 3880800 | T34: 3418800 | U34: 3072300 | V34: 3072300 | W34: 2772000 | X34: 2517900 | Y34: 2240700 | Z34: 2032800 | AA34: 1778700 | AB34: 1683990
H35: 3 year | I35: KL4085WA*TG | O35: 5266800 | P35: 5266800 | Q35: 5266800 | R35: 5266800 | S35: 4781700 | T35: 4204200 | U35: 3788400 | V35: 3788400 | W35: 3418800 | X35: 3118500 | Y35: 2748900 | Z35: 2517900 | AA35: 2194500 | AB35: 2079000
G36: Successive Plus | H36: 1 month | I36: KL4085WA*M4 | O36: 313929 | P36: 313929 | Q36: 313929 | R36: 313929 | S36: 284130 | T36: 251097 | U36: 224532 | V36: 224532 | W36: 204897 | X36: 185031 | Y36: 165165 | Z36: 148764 | AA36: 132132 | AB36: 122199
H37: 1 year | I37: KL4085WA*F4 | O37: 3118500 | P37: 3118500 | Q37: 3118500 | R37: 3118500 | S37: 2841300 | T37: 2517900 | U37: 2263800 | V37: 2263800 | W37: 2032800 | X37: 1848000 | Y37: 1637790 | Z37: 1489950 | AA37: 1309770 | AB37: 1233540
H38: 2 year | I38: KL4085WA*D4 | O38: 4689300 | P38: 4689300 | Q38: 4689300 | R38: 4689300 | S38: 4273500 | T38: 3765300 | U38: 3395700 | V38: 3395700 | W38: 3072300 | X38: 2772000 | Y38: 2448600 | Z38: 2240700 | AA38: 1963500 | AB38: 1848000
H39: 3 year | I39: KL4085WA*T4 | O39: 5798100 | P39: 5798100 | Q39: 5798100 | R39: 5798100 | S39: 5266800 | T39: 4620000 | U39: 4181100 | V39: 4181100 | W39: 3765300 | X39: 3418800 | Y39: 3026100 | Z39: 2748900 | AA39: 2425500 | AB39: 2286900
B40: 2006 | C40: Kaspersky Next XDR Expert | D40: User | E40: License | F40: User | G40: Successive | H40: 1 month | I40: KL4054WA*MG | W40: 481250 | X40: 360503 | Y40: 302753 | Z40: 293997 | AA40: 288750 | AB40: 283503
H41: 1 year | I41: KL4054WA*FG | W41: 5293750 | X41: 3965500 | Y41: 3330250 | Z41: 3234000 | AA41: 3176250 | AB41: 3118500
H42: 2 year | I42: KL4054WA*DG | W42: 7911750 | X42: 5967500 | Y42: 4985750 | Z42: 4851000 | AA42: 4793250 | AB42: 4677750
H43: 3 year | I43: KL4054WA*TG | W43: 9759750 | X43: 7353500 | Y43: 6179250 | Z43: 5967500 | AA43: 5871250 | AB43: 5775000
G44: Successive Plus | H44: 1 month | I44: KL4054WA*M4 | W44: 577500 | X44: 432597 | Y44: 363297 | Z44: 352803 | AA44: 346500 | AB44: 340197
H45: 1 year | I45: KL4054WA*F4 | W45: 6352500 | X45: 4758600 | Y45: 3996300 | Z45: 3880800 | AA45: 3811500 | AB45: 3742200
H46: 2 year | I46: KL4054WA*D4 | W46: 9494100 | X46: 7161000 | Y46: 5982900 | Z46: 5821200 | AA46: 5751900 | AB46: 5613300
...

Sheet xSP
C7: =CONCATENATE("Price List applicable for ",Data!A9,". Effective from ",Data!A11,". ") -> Price List applicable for Vietnam. Effective from July 1, 2026.
C8: =CONCATENATE(Data!A5,". ",Data!A7) -> Kaspersky Lab. 39A/3 Leningradskoe Shosse Moscow, 125212. 0
B9: Max of Price | J9: Band
B10: Code | C10: Product | D10: LicenceDescription | E10: Package | F10: LicenceObject | G10: Type | H10: Term | I10: SKU | J10: Band P: 250-499 | K10: Band Q: 500-999 | L10: Band R: 1000-1499 | M10: Band S: 1500-2499 | N10: Band T: 2500-4999 | O10: Band U: 5000-9999 | P10: Band V: 10000+
B11: 5111 | C11: Kaspersky Anti-Virus for xSP | D11: TrafficD | E11: Traffic Licence | F11: Mb of traffic per day | G11: Base | H11: 1 year | I11: KL5111NQ*FS | J11: 8 | K11: 5.5 | L11: 5 | M11: 4.5 | N11: 4 | O11: 3.5 | P11: 3
B12: 5811 | C12: Kaspersky Security for xSP | D12: TrafficD | E12: Traffic Licence | F12: Mb of traffic per day | G12: Base | H12: 1 year | I12: KL5811NQ*FS | J12: 15 | K12: 10.5 | L12: 9.5 | M12: 8.5 | N12: 7.5 | O12: 6.5 | P12: 5.5

Sheet Traffic
C7: =CONCATENATE("Price List applicable for ",Data!A9,". Effective from ",Data!A11,". ") -> Price List applicable for Vietnam. Effective from July 1, 2026.
C8: =CONCATENATE(Data!A5,". ",Data!A7) -> Kaspersky Lab. 39A/3 Leningradskoe Shosse Moscow, 125212. 0
B9: Max of Price | J9: Band
B10: Code | C10: Product | D10: LicenceDescription | E10: Package | F10: LicenceObject | G10: Type | H10: Term | I10: SKU | J10: Band P: 250-499 | K10: Band Q: 500-999 | L10: Band R: 1000-1499 | M10: Band S: 1500-2499 | N10: Band T: 2500-4999 | O10: Band U: 5000-9999 | P10: Band V: 10000+
B11: 5111 | C11: Kaspersky Anti-Virus for xSP | D11: TrafficD | E11: Traffic Licence | F11: Mb of traffic per day | G11: Base | H11: 1 year | I11: KL5111NQ*FS | J11: 8 | K11: 5.5 | L11: 5 | M11: 4.5 | N11: 4 | O11: 3.5 | P11: 3
B12: 5811 | C12: Kaspersky Security for xSP | D12: TrafficD | E12: Traffic Licence | F12: Mb of traffic per day | G12: Base | H12: 1 year | I12: KL5811NQ*FS | J12: 15 | K12: 10.5 | L12: 9.5 | M12: 8.5 | N12: 7.5 | O12: 6.5 | P12: 5.5

Sheet ProfessionalServices
C7: =CONCATENATE("Price List applicable for ",Data!A9,". Effective from ",Data!A11,". ") -> Price List applicable for Vietnam. Effective from July 1, 2026. | T7: * For additional details please see
C8: =CONCATENATE(Data!A5,". ",Data!A7) -> Kaspersky Lab. 39A/3 Leningradskoe Shosse Moscow, 125212. 0 | T8: specifications in Comment section
B9: Max of Price | J9: Band
B10: Code | C10: Product | D10: LicenceDescription | E10: Package | F10: LicenceObject | G10: Type | H10: Term | I10: SKU | K10: Band A: 1-1 | L10: Band B: 2-2 | M10: Band C: 3-3 | N10: Band D: 4-4 | O10: Band E: 5-9 | P10: Band K: 10-14 | Q10: Band M: 15-19 | R10: Band N: 20-24 | S10: Band P: 25-49 | T10: Band Q: 50-99 | U10: Band R: 100-149 | V10: Band S: 150-249
B11: 3000 | C11: Premium Support | D11: (blank) | E11: - | F11: - | G11: - | H11: - | I11: -
B12: 3001 | C12: Kaspersky Enhanced Support | D12: Case | E12: Certificate | H12: 1 year | I12: KL7122WL*FZ | J12: 377338500
H13: 2 year | I13: KL7122WL*DZ | J13: 754677000
H14: 3 year | I14: KL7122WL*TZ | J14: 1132015500
B15: 3002 | C15: Kaspersky Enhanced Support with TAM | D15: Case | E15: Certificate | H15: 1 year | I15: KL7124WL*FZ | J15: 754677000
H16: 2 year | I16: KL7124WL*DZ | J16: 1509354000
H17: 3 year | I17: KL7124WL*TZ | J17: 2264031000
B18: 3003 | C18: Kaspersky Enhanced Support Pro | D18: Case | E18: Certificate | F18: Case | H18: 1 year | I18: KL7129WL*FZ | J18: 1837578600
H19: 2 year | I19: KL7129WL*DZ | J19: 3675157200
H20: 3 year | I20: KL7129WL*TZ | J20: 5512735800
B21: 3004 | C21: Kaspersky Maintenance Service Agreement for MSP | D21: Case | E21: Certificate. | H21: 1 year | I21: KL7133W1*FZ | K21: 12912900 | L21: 11342100 | M21: 11342100 | N21: 11342100 | O21: 9725100 | P21: 8154300 | Q21: 8154300 | R21: 8154300 | S21: 8154300
B22: 3007 | C22: Kaspersky Maintenance Service Agreement for Partners | D22: Incident | E22: Certificate. | F22: Incident | H22: 1 year | I22: KL7227W1*FZ | O22: 16863000 | P22: 16863000 | Q22: 16863000
B23: 6050 | C23: Professional Services | D23: - | E23: - | F23: - | G23: - | H23: - | I23: -
B24: 6051 | C24: Kaspersky Professional Services - 4 Hours, Remote | D24: Day | E24: Certificate. | H24: 1 year | I24: KL7221W1*FZ | K24: 25155900
B25: 6052 | C25: Kaspersky Professional Services - 8 Hours, On-site | D25: Day | E25: Certificate. | H25: 1 year | I25: KL7224W1*FZ | K25: 92238300 | L25: 92238300 | M25: 92238300 | N25: 92238300 | O25: 92238300 | P25: 92238300 | Q25: 92238300 | R25: 92238300 | S25: 92238300 | T25: 92238300 | U25: 92238300 | V25: 92238300
B26: 6053 | C26: Kaspersky Professional Services - 8 Hours, Remote | D26: Day | E26: Certificate. | H26: 1 year | I26: KL7222W1*FZ | K26: 47516700 | L26: 47516700 | M26: 47516700 | N26: 47516700 | O26: 47516700 | P26: 47516700 | Q26: 47516700 | R26: 47516700 | S26: 47516700 | T26: 47516700 | U26: 47516700 | V26: 47516700
B27: 6054 | C27: Kaspersky Deployment service - 8 hours | D27: Case | E27: Certificate | H27: 1 year | I27: KL7231WL*FZ | J27: 47516700
B28: 6055 | C28: Kaspersky Disk Encryption service - 8 hours | D28: Case | E28: Certificate | H28: 1 year | I28: KL7232WL*FZ | J28: 47516700
B29: 6056 | C29: Kaspersky Upgrade service - 8 hours | D29: Case | E29: Certificate | H29: 1 year | I29: KL7234WL*FZ | J29: 47516700
B30: 6057 | C30: Kaspersky Health Check service - 2 hours | D30: Case | E30: Certificate | H30: 1 year | I30: KL7267WL*FZ | J30: 11896500
B31: 6058 | C31: Kaspersky Health Check service - 4 hours | D31: Case | E31: Certificate | H31: 1 year | I31: KL7268WL*FZ | J31: 23769900
B32: 6059 | C32: Kaspersky Health Check service - 8 hours | D32: Case | E32: Certificate | H32: 1 year | I32: KL7269WL*FZ | J32: 47516700
B33: 6061 | C33: Kaspersky Vulnerability and Patch management service - 8 hours | D33: Case | E33: Certificate | H33: 1 year | I33: KL7299WL*FZ | J33: 47516700
B34: 6062 | C34: Kaspersky Essential Installation service for Kaspersky Unified Monitoring and Analysis Platform | D34: Case | E34: Certificate | F34: Case | H34: 1 year | I34: KL7106WL*FZ | J34: 403891950
B35: 6063 | C35: Kaspersky Essential Installation service for Kaspersky XDR | D35: Case | E35: Certificate | F35: Case | H35: 1 year | I35: KL7107WL*FZ | J35: 605837925

Sheet SecurityServices
C7: =CONCATENATE("Price List applicable for ",Data!A9,". Effective from ",Data!A11,". ") -> Price List applicable for Vietnam. Effective from July 1, 2026. | W7: * For additional details please see
C8: =CONCATENATE(Data!A5,". ",Data!A7) -> Kaspersky Lab. 39A/3 Leningradskoe Shosse Moscow, 125212. 0 | W8: specifications in Comment section
B9: Max of Price | J9: Band
B10: Code | C10: Product | D10: LicenceDescription | E10: Package | F10: LicenceObject | G10: Type | H10: Term | I10: SKU | J10: Band Z: 1 | K10: Band A: 1 | L10: Band A: 1-1 | M10: Band B: 3 | N10: Band C: 5 | O10: Band D: 10 | P10: Band F: 20 | Q10: Band Q: 50-99 | R10: Band R: 100-149 | S10: Band S: 150-249 | T10: Band T: 250-499 | U10: Band U: 400 | V10: Band U: 500-999 | W10: Band W: 1000 | X10: Band 2: 2000 | Y10: Band X: 5000 | Z10: Band Y: 10000
B11: 5000 | C11: Security Awareness | D11: (blank) | E11: - | F11: - | G11: - | H11: - | I11: -
B12: 5001 | C12: Kaspersky Interactive Protection Simulation Training | D12: Case | E12: Certificate | G12: Base | H12: 1 year | I12: KL7556WL*FS | K12: 270015900 | M12: 665395500 | N12: 964309500
G13: Renewal | H13: 1 year | I13: KL7556WL*FR | K13: 270015900 | M13: 665395500 | N13: 964309500
B14: 8000 | C14: Threat Intelligence | D14: (blank) | E14: - | F14: - | G14: - | H14: - | I14: -
B15: 8001 | C15: Kaspersky Ask the Analyst | D15: Case | E15: Certificate | G15: Base | H15: 1 year | I15: KL7798WL*FS | N15: 566019300 | O15: 1132015500 | P15: 2264031000
H16: 3 year | I16: KL7798WL*TS | N16: 1443311100 | O16: 2886622200 | P16: 5773290600
H17: 2 year | I17: KL7798WL*DS | N17: 1018825500 | O17: 2037627900 | P17: 4075255800
B18: 8002 | C18: Kaspersky Takedown Service | D18: Queries per month | E18: Certificate | G18: Base | H18: 1 year | I18: KL7937WL*FS | O18: 594801900
B19: 8003 | C19: Kaspersky Incident Response Retainer Remote | D19: Hour | E19: Certificate. | H19: 1 year | I19: KL7056W1*FZ | Q19: 11665500 | R19: 10302600 | S19: 9609600 | T19: 9124500 | V19: 8662500
H20: 3 year | I20: KL7056W1*TZ | T20: 10493175 | V20: 9961875
H21: 2 year | I21: KL7056W1*DZ | S21: 10570560 | T21: 10036950 | V21: 9528750
B22: 8004 | C22: Kaspersky Incident Response Retainer On-site | D22: Hour | E22: Certificate. | H22: 1 year | I22: KL7057W1*FZ | Q22: 14414400 | R22: 13721400 | S22: 11845064 | T22: 11235389 | V22: 10712812
H23: 3 year | I23: KL7057W1*TZ | T23: 12920699 | V23: 12319736
H24: 2 year | I24: KL7057W1*DZ | S24: 13029577 | T24: 12358929 | V24: 11784102
B25: 8005 | C25: Kaspersky Incident Response Emergency (Remote) | D25: Incident | E25: Certificate. | F25: Incident | H25: 1 year | I25: KL7858W1*FZ | L25: 820000000
B26: 8006 | C26: Kaspersky Incident Response Emergency (On-site) | D26: Incident | E26: Certificate. | F26: Incident | H26: 1 year | I26: KL7859W1*FZ | L26: 1020000000
B27: 8007 | C27: Kaspersky Adversary Attack Emulation | D27: Case | E27: Certificate | F27: Case | H27: 1 year | I27: KL7881WL*FZ | J27: 787500000
B28: 8008 | C28: Kaspersky Incident Response Plan Development | D28: Case | E28: Certificate | F28: Case | H28: 1 year | I28: KL7882WL*FZ | J28: 1022500000
B29: 8009 | C29: Kaspersky SOC Maturity Assessment by SOC-CMM methodology | D29: Case | E29: Certificate | F29: Case | H29: 1 year | I29: KL7883WL*FZ | J29: 762500000
B30: 8011 | C30: Kaspersky Remote Compromise Assessment* | D30: Node | E30: Certificate | F30: Node | H30: 1 year | I30: KL7884WL*FZ | U30: 1102500000 | W30: 1102500000 | X30: 1190000000 | Y30: 1312499999 | Z30: 1592500000

Sheet SIEM
C7: =CONCATENATE("Price List applicable for ",Data!A9,". Effective from ",Data!A11,". ") -> Price List applicable for Vietnam. Effective from July 1, 2026. | U7: * For additional details please see
C8: =CONCATENATE(Data!A5,". ",Data!A7) -> Kaspersky Lab. 39A/3 Leningradskoe Shosse Moscow, 125212. 0 | U8: specifications in Comment section
B9: Max of Price | J9: Band
B10: Code | C10: Product | D10: LicenceDescription | E10: Package | F10: LicenceObject | G10: Type | H10: Term | I10: SKU | J10: Band E: 5-9 | K10: Band K: 10-14 | L10: Band M: 15-19 | M10: Band N: 20-24 | N10: Band P: 25-49 | O10: Band Q: 50-99 | P10: Band R: 100-149 | Q10: Band S: 150-249 | R10: Band T: 250-499 | S10: Band U: 500-999 | T10: Band V: 1000-1499 | U10: Band W: 1500-2499 | V10: Band X: 2500-4999 | W10: Band Y: 5000+
B11: 4000 | C11: Kaspersky Anti Targeted Attack Platform | D11: - | E11: - | F11: - | G11: - | H11: - | I11: -
B12: 4032 | C12: Kaspersky Unified Monitoring and Analysis Platform | D12: * 100 events per second | E12: License | G12: Base Premium | H12: 1 year | I12: KL4032WA*FA | J12: 175329000 | K12: 132501600 | L12: 110695200 | M12: 107461200 | N12: 105058800 | O12: 104250300 | P12: 103441800 | Q12: 93116100 | R12: 88449900 | S12: 84037800 | T12: 79833600 | U12: 79833600 | V12: 79833600 | W12: 79833600
H13: 2 year | I13: KL4032WA*DA | J13: 280526400 | K13: 212011800 | L13: 177107700 | M13: 171956400 | N13: 168098700 | O13: 166805100 | P13: 165511500 | Q13: 148971900 | R13: 141510600 | S13: 134442000 | T13: 127719900 | U13: 127719900 | V13: 127719900 | W13: 127719900
H14: 3 year | I14: KL4032WA*TA | J14: 403256700 | K14: 304758300 | L14: 254585100 | M14: 247193100 | N14: 241626000 | O14: 239778000 | P14: 237930000 | Q14: 214137000 | R14: 203441700 | S14: 193254600 | T14: 183598800 | U14: 183598800 | V14: 183598800 | W14: 183598800
G15: Renewal Premium Plus | H15: 1 year | I15: KL4032WA*F6 | J15: 132963600 | K15: 100485000 | L15: 83945400 | M15: 81496800 | N15: 79671900 | O15: 79071300 | P15: 78447600 | Q15: 70616700 | R15: 67082400 | S15: 63709800 | T15: 60545100 | U15: 60545100 | V15: 60545100 | W15: 60545100
H16: 2 year | I16: KL4032WA*D6 | J16: 252621600 | K16: 190921500 | L16: 159482400 | M16: 154839300 | N16: 151374300 | O16: 150219300 | P16: 149064300 | Q16: 134141700 | R16: 127442700 | S16: 121067100 | T16: 115014900 | U16: 115014900 | V16: 115014900 | W16: 115014900
H17: 3 year | I17: KL4032WA*T6 | J17: 372279600 | K17: 281334900 | L17: 235019400 | M17: 228204900 | N17: 223076700 | O17: 221367300 | P17: 219657900 | Q17: 197689800 | R17: 187803000 | S17: 178424400 | T17: 169507800 | U17: 169507800 | V17: 169507800 | W17: 169507800
G18: Renewal Premium | H18: 1 year | I18: KL4032WA*FL | J18: 122730300 | K18: 92746500 | L18: 77477400 | M18: 75236700 | N18: 73550400 | O18: 72972900 | P18: 72418500 | Q18: 65165100 | R18: 61908000 | S18: 58812600 | T18: 55878900 | U18: 55878900 | V18: 55878900 | W18: 55878900
H19: 2 year | I19: KL4032WA*DL | J19: 233194500 | K19: 176229900 | L19: 147216300 | M19: 142942800 | N19: 139731900 | O19: 138669300 | P19: 137583600 | Q19: 123839100 | R19: 117648300 | S19: 111757800 | T19: 106167600 | U19: 106167600 | V19: 106167600 | W19: 106167600
H20: 3 year | I20: KL4032WA*TL | J20: 343635600 | K20: 259713300 | L20: 216955200 | M20: 210648900 | N20: 205913400 | O20: 204342600 | P20: 202771800 | Q20: 182490000 | R20: 173365500 | S20: 164703000 | T20: 156456300 | U20: 156456300 | V20: 156456300 | W20: 156456300
G21: Base Premium Plus | H21: 1 year | I21: KL4032WA*F5 | J21: 189951300 | K21: 143543400 | L21: 119912100 | M21: 116424000 | N21: 113813700 | O21: 112935900 | P21: 112081200 | Q21: 100854600 | R21: 95818800 | S21: 91037100 | T21: 86486400 | U21: 86486400 | V21: 86486400 | W21: 86486400
H22: 2 year | I22: KL4032WA*D5 | J22: 303903600 | K22: 229660200 | L22: 191845500 | M22: 186278400 | N22: 182097300 | O22: 180711300 | P22: 179325300 | Q22: 161376600 | R22: 153314700 | S22: 145645500 | T22: 138369000 | U22: 138369000 | V22: 138369000 | W22: 138369000
H23: 3 year | I23: KL4032WA*T5 | J23: 436867200 | K23: 330145200 | L23: 275790900 | M23: 267775200 | N23: 261769200 | O23: 259759500 | P23: 257772900 | Q23: 231993300 | R23: 220397100 | S23: 209378400 | T23: 198891000 | U23: 198891000 | V23: 198891000 | W23: 198891000
B24: 4034 | C24: Kaspersky Unified Monitoring and Analysis Platform with Netflow support | D24: * 100 events per second | E24: License | G24: Base Premium | H24: 1 year | I24: KL4034WA*FA | J24: 201639900 | K24: 152367600 | L24: 127281000 | M24: 123585000 | N24: 120813000 | O24: 119889000 | P24: 118941900 | Q24: 107045400 | R24: 101709300 | S24: 96604200 | T24: 91776300 | U24: 91776300 | V24: 91776300 | W24: 91776300
H25: 2 year | I25: KL4034WA*DA | J25: 322614600 | K25: 243797400 | L25: 203672700 | M25: 197712900 | N25: 193277700 | O25: 191822400 | P25: 190320900 | Q25: 171286500 | R25: 162716400 | S25: 154585200 | T25: 146846700 | U25: 146846700 | V25: 146846700 | W25: 146846700
H26: 3 year | I26: KL4034WA*TA | J26: 463755600 | K26: 350473200 | L26: 292769400 | M26: 284222400 | N26: 277846800 | O26: 275744700 | P26: 273573300 | Q26: 246222900 | R26: 233910600 | S26: 222222000 | T26: 211110900 | U26: 211110900 | V26: 211110900 | W26: 211110900
G27: Renewal Premium Plus | H27: 1 year | I27: KL4034WA*F6 | J27: 152898900 | K27: 115546200 | L27: 96534900 | M27: 93716700 | N27: 91614600 | O27: 90921600 | P27: 90205500 | Q27: 81173400 | R27: 77130900 | S27: 73273200 | T27: 69600300 | U27: 69600300 | V27: 69600300 | W27: 69600300
H28: 2 year | I28: KL4034WA*D6 | J28: 290528700 | K28: 219542400 | L28: 183414000 | M28: 178054800 | N28: 174058500 | O28: 172741800 | P28: 171378900 | Q28: 154238700 | R28: 146523300 | S28: 139200600 | T28: 132247500 | U28: 132247500 | V28: 132247500 | W28: 132247500
H29: 3 year | I29: KL4034WA*T6 | J29: 428135400 | K29: 323538600 | L29: 270270000 | M29: 262392900 | N29: 256502400 | O29: 254562000 | P29: 252552300 | Q29: 227304000 | R29: 215938800 | S29: 205151100 | T29: 194894700 | U29: 194894700 | V29: 194894700 | W29: 194894700
G30: Renewal Premium | H30: 1 year | I30: KL4034WA*FL | J30: 141141000 | K30: 106652700 | L30: 89096700 | M30: 86509500 | N30: 84569100 | O30: 83922300 | P30: 83252400 | Q30: 74936400 | R30: 71194200 | S30: 67636800 | T30: 64241100 | U30: 64241100 | V30: 64241100 | W30: 64241100
H31: 2 year | I31: KL4034WA*DL | J31: 268167900 | K31: 202656300 | L31: 169299900 | M31: 164356500 | N31: 160660500 | O31: 159459300 | P31: 158188800 | Q31: 142388400 | R31: 135250500 | S31: 128505300 | T31: 122083500 | U31: 122083500 | V31: 122083500 | W31: 122083500
H32: 3 year | I32: KL4034WA*TL | J32: 395194800 | K32: 298659900 | L32: 249480000 | M32: 242203500 | N32: 236775000 | O32: 234973200 | P32: 233125200 | Q32: 209817300 | R32: 199329900 | S32: 189373800 | T32: 179902800 | U32: 179902800 | V32: 179902800 | W32: 179902800
G33: Base Premium Plus | H33: 1 year | I33: KL4034WA*F5 | J33: 218433600 | K33: 165072600 | L33: 137907000 | M33: 133864500 | N33: 130861500 | O33: 129868200 | P33: 128851800 | Q33: 115962000 | R33: 110163900 | S33: 104666100 | T33: 99422400 | U33: 99422400 | V33: 99422400 | W33: 99422400
H34: 2 year | I34: KL4034WA*D5 | J34: 349503000 | K34: 264125400 | L34: 220628100 | M34: 214206300 | N34: 209401500 | O34: 207807600 | P34: 206167500 | Q34: 185562300 | R34: 176276100 | S34: 167475000 | T34: 159089700 | U34: 159089700 | V34: 159089700 | W34: 159089700
H35: 3 year | I35: KL4034WA*T5 | J35: 502401900 | K35: 379671600 | L35: 317163000 | M35: 307899900 | N35: 300993000 | O35: 298729200 | P35: 296373000 | Q35: 266735700 | R35: 253407000 | S35: 240725100 | T35: 228690000 | U35: 228690000 | V35: 228690000 | W35: 228690000
B36: 4047 | C36: Kaspersky Unified Monitoring and Analysis Platform with Netflow support and TI | D36: * 100 events per second | E36: License | G36: Base Premium | H36: 1 year | I36: KL4047WA*FA | J36: 302425200 | K36: 228551400 | L36: 190944600 | M36: 185400600 | N36: 181196400 | O36: 179810400 | P36: 178424400 | Q36: 160591200 | R36: 152552400 | S36: 144929400 | T36: 137676000 | U36: 137676000 | V36: 137676000 | W36: 137676000
H37: 2 year | I37: KL4047WA*DA | J37: 483875700 | K37: 365673000 | L37: 305497500 | M37: 296627100 | N37: 289928100 | O37: 287710500 | P37: 285492900 | Q37: 256941300 | R37: 244097700 | S37: 231900900 | T37: 220304700 | U37: 220304700 | V37: 220304700 | W37: 220304700
H38: 3 year | I38: KL4047WA*TA | J38: 695587200 | K38: 525663600 | L38: 439154100 | M38: 426402900 | N38: 416770200 | O38: 413582400 | P38: 410394600 | Q38: 369369000 | R38: 350889000 | S38: 333356100 | T38: 316677900 | U38: 316677900 | V38: 316677900 | W38: 316677900
G39: Renewal Premium Plus | H39: 1 year | I39: KL4047WA*F6 | J39: 229336800 | K39: 173319300 | L39: 144790800 | M39: 140586600 | N39: 137421900 | O39: 136359300 | P39: 135319800 | Q39: 121783200 | R39: 115684800 | S39: 109909800 | T39: 104412000 | U39: 104412000 | V39: 104412000 | W39: 104412000
H40: 2 year | I40: KL4047WA*D6 | J40: 435735300 | K40: 329313600 | L40: 275097900 | M40: 267128400 | N40: 261076200 | O40: 259089600 | P40: 257103000 | Q40: 231392700 | R40: 219819600 | S40: 208824000 | T40: 198382800 | U40: 198382800 | V40: 198382800 | W40: 198382800
H41: 3 year | I41: KL4047WA*T6 | J41: 642156900 | K41: 485284800 | L41: 405428100 | M41: 393647100 | N41: 384753600 | O41: 381819900 | P41: 378863100 | Q41: 340979100 | R41: 323931300 | S41: 307738200 | T41: 292353600 | U41: 292353600 | V41: 292353600 | W41: 292353600
G42: Renewal Premium | H42: 1 year | I42: KL4047WA*FL | J42: 211688400 | K42: 159990600 | L42: 133656600 | M42: 129775800 | N42: 126842100 | O42: 125871900 | P42: 124901700 | Q42: 112404600 | R42: 106791300 | S42: 101455200 | T42: 96373200 | U42: 96373200 | V42: 96373200 | W42: 96373200
H43: 2 year | I43: KL4047WA*DL | J43: 402217200 | K43: 303972900 | L43: 253938300 | M43: 246569400 | N43: 241002300 | O43: 239154300 | P43: 237306300 | Q43: 213582600 | R43: 202910400 | S43: 192769500 | T43: 183113700 | U43: 183113700 | V43: 183113700 | W43: 183113700
H44: 3 year | I44: KL4047WA*TL | J44: 592746000 | K44: 447955200 | L44: 374243100 | M44: 363363000 | N44: 355162500 | O44: 352436700 | P44: 349734000 | Q44: 314760600 | R44: 299029500 | S44: 284060700 | T44: 269854200 | U44: 269854200 | V44: 269854200 | W44: 269854200
G45: Base Premium Plus | H45: 1 year | I45: KL4047WA*F5 | J45: 327627300 | K45: 247585800 | L45: 206837400 | M45: 200831400 | N45: 196303800 | O45: 194802300 | P45: 193300800 | Q45: 173966100 | R45: 165280500 | S45: 157010700 | T45: 149156700 | U45: 149156700 | V45: 149156700 | W45: 149156700
H46: 2 year | I46: KL4047WA*D5 | J46: 524208300 | K46: 396165000 | L46: 330953700 | M46: 321344100 | N46: 314090700 | O46: 311688300 | P46: 309285900 | Q46: 278355000 | R46: 264448800 | S46: 251212500 | T46: 238646100 | U46: 238646100 | V46: 238646100 | W46: 238646100
...

Sheet ScanEngine
C7: =CONCATENATE("Price List applicable for ",Data!A9,". Effective from ",Data!A11,". ") -> Price List applicable for Vietnam. Effective from July 1, 2026. | K7: * For additional details please see
C8: =CONCATENATE(Data!A5,". ",Data!A7) -> Kaspersky Lab. 39A/3 Leningradskoe Shosse Moscow, 125212. 0 | K8: specifications in Comment section
B9: Max of Price | J9: Band
B10: Code | C10: Product | D10: LicenceDescription | E10: Package | F10: LicenceObject | G10: Type | H10: Term | I10: SKU | J10: Band 1: 250+ | K10: Band Y: 1-10000
B11: 4000 | C11: Threat Intelligence | D11: - | E11: - | F11: - | G11: - | H11: - | I11: -
B12: 4001 | C12: Kaspersky Scan Engine | D12: Node | E12: Technology Licence | G12: Base | H12: 1 year | I12: KL6910WH*FS | J12: 304920
H13: 2 year | I13: KL6910WH*DS | J13: 457380
H14: 3 year | I14: KL6910WH*TS | J14: 593670
B15: 4002 | C15: Kaspersky Scan Engine, Server | D15: Svr | E15: Technology Licence | G15: Base | H15: 1 year | I15: KL6916WH*FS | K15: 293393100
H16: 2 year | I16: KL6916WH*DS | K16: 440055000
H17: 3 year | I17: KL6916WH*TS | K17: 572071500

Sheet SD-WAN
C7: =CONCATENATE("Price List applicable for ",Data!A9,". Effective from ",Data!A11,". ") -> Price List applicable for Vietnam. Effective from July 1, 2026. | AB7: * For additional details please see
C8: =CONCATENATE(Data!A5,". ",Data!A7) -> Kaspersky Lab. 39A/3 Leningradskoe Shosse Moscow, 125212. 0 | AB8: specifications in Comment section
B9: Max of Price | J9: Band
B10: Code | C10: Product | D10: LicenceDescription | E10: Package | F10: LicenceObject | G10: Type | H10: Term | I10: SKU | J10: Band A: 1 | K10: Band A: 1-1 | L10: Band B: 2-2 | M10: Band C: 3-3 | N10: Band D: 4-4 | O10: Band E: 5-9 | P10: Band K: 10-14 | Q10: Band M: 15-19 | R10: Band N: 20-24 | S10: Band P: 25-49 | T10: Band Q: 50-99 | U10: Band R: 100-149 | V10: Band S: 150-249 | W10: Band T: 250-499 | X10: Band U: 500-999 | Y10: Band V: 1000-1499 | Z10: Band W: 1500-2499 | AA10: Band X: 2500-4999 | AB10: Band Y: 5000+
B11: 4000 | C11: Kaspersky Anti Targeted Attack Platform* | D11: - | E11: - | F11: - | G11: - | H11: - | I11: -
B12: 4001 | C12: Kaspersky SD-WAN Advanced CPE 1 Gbps | D12: Dvc | E12: License | G12: Base Premium Plus | H12: 1 year | I12: KL4245WA*F5 | K12: 591544800 | L12: 591544800 | M12: 591544800 | N12: 591544800 | O12: 591544800 | P12: 591544800 | Q12: 591544800 | R12: 591544800 | S12: 591544800 | T12: 591544800 | U12: 502817700 | V12: 502817700 | W12: 473226600 | X12: 473226600 | Y12: 410140500 | Z12: 410140500 | AA12: 410140500 | AB12: 410140500
H13: 2 year | I13: KL4245WA*D5 | K13: 1025339700 | L13: 1025339700 | M13: 1025339700 | N13: 1025339700 | O13: 1025339700 | P13: 1025339700 | Q13: 1025339700 | R13: 1025339700 | S13: 1025339700 | T13: 1025339700 | U13: 871539900 | V13: 871539900 | W13: 820257900 | X13: 820257900 | Y13: 757171800 | Z13: 757171800 | AA13: 757171800 | AB13: 757171800
H14: 3 year | I14: KL4245WA*T5 | K14: 1538021100 | L14: 1538021100 | M14: 1538021100 | N14: 1538021100 | O14: 1538021100 | P14: 1538021100 | Q14: 1538021100 | R14: 1538021100 | S14: 1538021100 | T14: 1538021100 | U14: 1307298300 | V14: 1307298300 | W14: 1230398400 | X14: 1230398400 | Y14: 1167312300 | Z14: 1167312300 | AA14: 1167312300 | AB14: 1167312300
G15: Renewal Premium Plus | H15: 1 year | I15: KL4245WA*F6 | K15: 512681400 | L15: 512681400 | M15: 512681400 | N15: 512681400 | O15: 512681400 | P15: 512681400 | Q15: 512681400 | R15: 512681400 | S15: 512681400 | T15: 512681400 | U15: 435758400 | V15: 435758400 | W15: 410140500 | X15: 410140500 | Y15: 347054400 | Z15: 347054400 | AA15: 347054400 | AB15: 347054400
H16: 2 year | I16: KL4245WA*D6 | K16: 899144400 | L16: 899144400 | M16: 899144400 | N16: 899144400 | O16: 899144400 | P16: 899144400 | Q16: 899144400 | R16: 899144400 | S16: 899144400 | T16: 899144400 | U16: 764286600 | V16: 764286600 | W16: 719310900 | X16: 719310900 | Y16: 656224800 | Z16: 656224800 | AA16: 656224800 | AB16: 656224800
H17: 3 year | I17: KL4245WA*T6 | K17: 1348716600 | L17: 1348716600 | M17: 1348716600 | N17: 1348716600 | O17: 1348716600 | P17: 1348716600 | Q17: 1348716600 | R17: 1348716600 | S17: 1348716600 | T17: 1348716600 | U17: 1146406800 | V17: 1146406800 | W17: 1078954800 | X17: 1078954800 | Y17: 1015868700 | Z17: 1015868700 | AA17: 1015868700 | AB17: 1015868700
G18: Base Premium | H18: 1 year | I18: KL4245WA*FA | K18: 512681400 | L18: 512681400 | M18: 512681400 | N18: 512681400 | O18: 512681400 | P18: 512681400 | Q18: 512681400 | R18: 512681400 | S18: 512681400 | T18: 512681400 | U18: 435758400 | V18: 435758400 | W18: 410140500 | X18: 410140500 | Y18: 378585900 | Z18: 378585900 | AA18: 378585900 | AB18: 378585900
H19: 2 year | I19: KL4245WA*DA | K19: 867589800 | L19: 867589800 | M19: 867589800 | N19: 867589800 | O19: 867589800 | P19: 867589800 | Q19: 867589800 | R19: 867589800 | S19: 867589800 | T19: 867589800 | U19: 737444400 | V19: 737444400 | W19: 694085700 | X19: 694085700 | Y19: 662508000 | Z19: 662508000 | AA19: 662508000 | AB19: 662508000
H20: 3 year | I20: KL4245WA*TA | K20: 1301407800 | L20: 1301407800 | M20: 1301407800 | N20: 1301407800 | O20: 1301407800 | P20: 1301407800 | Q20: 1301407800 | R20: 1301407800 | S20: 1301407800 | T20: 1301407800 | U20: 1106166600 | V20: 1106166600 | W20: 1041117000 | X20: 1041117000 | Y20: 1009562400 | Z20: 1009562400 | AA20: 1009562400 | AB20: 1009562400
G21: Renewal Premium | H21: 1 year | I21: KL4245WA*FL | K21: 433794900 | L21: 433794900 | M21: 433794900 | N21: 433794900 | O21: 433794900 | P21: 433794900 | Q21: 433794900 | R21: 433794900 | S21: 433794900 | T21: 433794900 | U21: 368722200 | V21: 368722200 | W21: 347054400 | X21: 347054400 | Y21: 315499800 | Z21: 315499800 | AA21: 315499800 | AB21: 315499800
H22: 2 year | I22: KL4245WA*DL | K22: 741394500 | L22: 741394500 | M22: 741394500 | N22: 741394500 | O22: 741394500 | P22: 741394500 | Q22: 741394500 | R22: 741394500 | S22: 741394500 | T22: 741394500 | U22: 630191100 | V22: 630191100 | W22: 593115600 | X22: 593115600 | Y22: 561561000 | Z22: 561561000 | AA22: 561561000 | AB22: 561561000
H23: 3 year | I23: KL4245WA*TL | K23: 1112103300 | L23: 1112103300 | M23: 1112103300 | N23: 1112103300 | O23: 1112103300 | P23: 1112103300 | Q23: 1112103300 | R23: 1112103300 | S23: 1112103300 | T23: 1112103300 | U23: 945275100 | V23: 945275100 | W23: 889673400 | X23: 889673400 | Y23: 858118800 | Z23: 858118800 | AA23: 858118800 | AB23: 858118800
B24: 4002 | C24: Kaspersky SD-WAN Advanced CPE 10 Gbps | D24: Dvc | E24: License | G24: Base Premium Plus | H24: 1 year | I24: KL4246WA*F5 | K24: 2253081600 | L24: 2253081600 | M24: 2253081600 | N24: 2253081600 | O24: 2253081600 | P24: 2253081600 | Q24: 2253081600 | R24: 2253081600 | S24: 2253081600 | T24: 2253081600 | U24: 1915128600 | V24: 1915128600 | W24: 1802469900 | X24: 1802469900 | Y24: 1562137500 | Z24: 1562137500 | AA24: 1562137500 | AB24: 1562137500
H25: 2 year | I25: KL4246WA*D5 | K25: 3905355300 | L25: 3905355300 | M25: 3905355300 | N25: 3905355300 | O25: 3905355300 | P25: 3905355300 | Q25: 3905355300 | R25: 3905355300 | S25: 3905355300 | T25: 3905355300 | U25: 3319562400 | V25: 3319562400 | W25: 3124298100 | X25: 3124298100 | Y25: 2883965700 | Z25: 2883965700 | AA25: 2883965700 | AB25: 2883965700
H26: 3 year | I26: KL4246WA*T5 | K26: 5858021400 | L26: 5858021400 | M26: 5858021400 | N26: 5858021400 | O26: 5858021400 | P26: 5858021400 | Q26: 5858021400 | R26: 5858021400 | S26: 5858021400 | T26: 5858021400 | U26: 4979320500 | V26: 4979320500 | W26: 4686412500 | X26: 4686412500 | Y26: 4446080100 | Z26: 4446080100 | AA26: 4446080100 | AB26: 4446080100
G27: Renewal Premium Plus | H27: 1 year | I27: KL4246WA*F6 | K27: 1952689200 | L27: 1952689200 | M27: 1952689200 | N27: 1952689200 | O27: 1952689200 | P27: 1952689200 | Q27: 1952689200 | R27: 1952689200 | S27: 1952689200 | T27: 1952689200 | U27: 1659781200 | V27: 1659781200 | W27: 1562137500 | X27: 1562137500 | Y27: 1321805100 | Z27: 1321805100 | AA27: 1321805100 | AB27: 1321805100
H28: 2 year | I28: KL4246WA*D6 | K28: 3424690500 | L28: 3424690500 | M28: 3424690500 | N28: 3424690500 | O28: 3424690500 | P28: 3424690500 | Q28: 3424690500 | R28: 3424690500 | S28: 3424690500 | T28: 3424690500 | U28: 2910992700 | V28: 2910992700 | W28: 2739752400 | X28: 2739752400 | Y28: 2499420000 | Z28: 2499420000 | AA28: 2499420000 | AB28: 2499420000
H29: 3 year | I29: KL4246WA*T6 | K29: 5137047300 | L29: 5137047300 | M29: 5137047300 | N29: 5137047300 | O29: 5137047300 | P29: 5137047300 | Q29: 5137047300 | R29: 5137047300 | S29: 5137047300 | T29: 5137047300 | U29: 4366477500 | V29: 4366477500 | W29: 4109628600 | X29: 4109628600 | Y29: 3869319300 | Z29: 3869319300 | AA29: 3869319300 | AB29: 3869319300
G30: Base Premium | H30: 1 year | I30: KL4246WA*FA | K30: 1952689200 | L30: 1952689200 | M30: 1952689200 | N30: 1952689200 | O30: 1952689200 | P30: 1952689200 | Q30: 1952689200 | R30: 1952689200 | S30: 1952689200 | T30: 1952689200 | U30: 1659781200 | V30: 1659781200 | W30: 1562137500 | X30: 1562137500 | Y30: 1441971300 | Z30: 1441971300 | AA30: 1441971300 | AB30: 1441971300
H31: 2 year | I31: KL4246WA*DA | K31: 3304524300 | L31: 3304524300 | M31: 3304524300 | N31: 3304524300 | O31: 3304524300 | P31: 3304524300 | Q31: 3304524300 | R31: 3304524300 | S31: 3304524300 | T31: 3304524300 | U31: 2808844500 | V31: 2808844500 | W31: 2643633300 | X31: 2643633300 | Y31: 2523467100 | Z31: 2523467100 | AA31: 2523467100 | AB31: 2523467100
H32: 3 year | I32: KL4246WA*TA | K32: 4956798000 | L32: 4956798000 | M32: 4956798000 | N32: 4956798000 | O32: 4956798000 | P32: 4956798000 | Q32: 4956798000 | R32: 4956798000 | S32: 4956798000 | T32: 4956798000 | U32: 4213278300 | V32: 4213278300 | W32: 3965438400 | X32: 3965438400 | Y32: 3845272200 | Z32: 3845272200 | AA32: 3845272200 | AB32: 3845272200
G33: Renewal Premium | H33: 1 year | I33: KL4246WA*FL | K33: 1652250600 | L33: 1652250600 | M33: 1652250600 | N33: 1652250600 | O33: 1652250600 | P33: 1652250600 | Q33: 1652250600 | R33: 1652250600 | S33: 1652250600 | T33: 1652250600 | U33: 1404433800 | V33: 1404433800 | W33: 1321805100 | X33: 1321805100 | Y33: 1201638900 | Z33: 1201638900 | AA33: 1201638900 | AB33: 1201638900
H34: 2 year | I34: KL4246WA*DL | K34: 2823859500 | L34: 2823859500 | M34: 2823859500 | N34: 2823859500 | O34: 2823859500 | P34: 2823859500 | Q34: 2823859500 | R34: 2823859500 | S34: 2823859500 | T34: 2823859500 | U34: 2400274800 | V34: 2400274800 | W34: 2259110700 | X34: 2259110700 | Y34: 2138944500 | Z34: 2138944500 | AA34: 2138944500 | AB34: 2138944500
H35: 3 year | I35: KL4246WA*TL | K35: 4235800800 | L35: 4235800800 | M35: 4235800800 | N35: 4235800800 | O35: 4235800800 | P35: 4235800800 | Q35: 4235800800 | R35: 4235800800 | S35: 4235800800 | T35: 4235800800 | U35: 3600435300 | V35: 3600435300 | W35: 3388654500 | X35: 3388654500 | Y35: 3268488300 | Z35: 3268488300 | AA35: 3268488300 | AB35: 3268488300
B36: 4003 | C36: Kaspersky SD-WAN Advanced CPE 100 Mbps | D36: Dvc | E36: License | G36: Base Premium Plus | H36: 1 year | I36: KL4242WA*F5 | K36: 134626800 | L36: 134626800 | M36: 134626800 | N36: 134626800 | O36: 134626800 | P36: 134626800 | Q36: 134626800 | R36: 134626800 | S36: 134626800 | T36: 134626800 | U36: 114414300 | V36: 114414300 | W36: 107715300 | X36: 107715300 | Y36: 93324000 | Z36: 93324000 | AA36: 93324000 | AB36: 93324000
H37: 2 year | I37: KL4242WA*D5 | K37: 233333100 | L37: 233333100 | M37: 233333100 | N37: 233333100 | O37: 233333100 | P37: 233333100 | Q37: 233333100 | R37: 233333100 | S37: 233333100 | T37: 233333100 | U37: 198359700 | V37: 198359700 | W37: 186694200 | X37: 186694200 | Y37: 172326000 | Z37: 172326000 | AA37: 172326000 | AB37: 172326000
H38: 3 year | I38: KL4242WA*T5 | K38: 350034300 | L38: 350034300 | M38: 350034300 | N38: 350034300 | O38: 350034300 | P38: 350034300 | Q38: 350034300 | R38: 350034300 | S38: 350034300 | T38: 350034300 | U38: 297528000 | V38: 297528000 | W38: 280018200 | X38: 280018200 | Y38: 265673100 | Z38: 265673100 | AA38: 265673100 | AB38: 265673100
G39: Renewal Premium Plus | H39: 1 year | I39: KL4242WA*F6 | K39: 116678100 | L39: 116678100 | M39: 116678100 | N39: 116678100 | O39: 116678100 | P39: 116678100 | Q39: 116678100 | R39: 116678100 | S39: 116678100 | T39: 116678100 | U39: 99168300 | V39: 99168300 | W39: 93324000 | X39: 93324000 | Y39: 78978900 | Z39: 78978900 | AA39: 78978900 | AB39: 78978900
H40: 2 year | I40: KL4242WA*D6 | K40: 204619800 | L40: 204619800 | M40: 204619800 | N40: 204619800 | O40: 204619800 | P40: 204619800 | Q40: 204619800 | R40: 204619800 | S40: 204619800 | T40: 204619800 | U40: 173943000 | V40: 173943000 | W40: 163709700 | X40: 163709700 | Y40: 149341500 | Z40: 149341500 | AA40: 149341500 | AB40: 149341500
H41: 3 year | I41: KL4242WA*T6 | K41: 306952800 | L41: 306952800 | M41: 306952800 | N41: 306952800 | O41: 306952800 | P41: 306952800 | Q41: 306952800 | R41: 306952800 | S41: 306952800 | T41: 306952800 | U41: 260914500 | V41: 260914500 | W41: 245553000 | X41: 245553000 | Y41: 231207900 | Z41: 231207900 | AA41: 231207900 | AB41: 231207900
G42: Base Premium | H42: 1 year | I42: KL4242WA*FA | K42: 116678100 | L42: 116678100 | M42: 116678100 | N42: 116678100 | O42: 116678100 | P42: 116678100 | Q42: 116678100 | R42: 116678100 | S42: 116678100 | T42: 116678100 | U42: 99168300 | V42: 99168300 | W42: 93324000 | X42: 93324000 | Y42: 86163000 | Z42: 86163000 | AA42: 86163000 | AB42: 86163000
H43: 2 year | I43: KL4242WA*DA | K43: 197458800 | L43: 197458800 | M43: 197458800 | N43: 197458800 | O43: 197458800 | P43: 197458800 | Q43: 197458800 | R43: 197458800 | S43: 197458800 | T43: 197458800 | U43: 167844600 | V43: 167844600 | W43: 157957800 | X43: 157957800 | Y43: 150773700 | Z43: 150773700 | AA43: 150773700 | AB43: 150773700
H44: 3 year | I44: KL4242WA*TA | K44: 296188200 | L44: 296188200 | M44: 296188200 | N44: 296188200 | O44: 296188200 | P44: 296188200 | Q44: 296188200 | R44: 296188200 | S44: 296188200 | T44: 296188200 | U44: 251766900 | V44: 251766900 | W44: 236959800 | X44: 236959800 | Y44: 229752600 | Z44: 229752600 | AA44: 229752600 | AB44: 229752600
